<?xml version="1.0" encoding="UTF-8"?>
<testng-results skipped="0" failed="6" ignored="0" total="6" passed="0">
  <reporter-output>
  </reporter-output>
  <suite name="Default suite" duration-ms="41" started-at="2019-11-27T10:50:54 MSK" finished-at="2019-11-27T10:50:54 MSK">
    <groups>
    </groups>
    <test name="Default test" duration-ms="41" started-at="2019-11-27T10:50:54 MSK" finished-at="2019-11-27T10:50:54 MSK">
      <class name="Tests.QuadratTest">
        <test-method status="FAIL" signature="checkSquare(java.lang.Double)[pri:0, instance:Tests.QuadratTest@5383967b]" name="checkSquare" duration-ms="6" started-at="2019-11-27T10:50:54 MSK" data-provider="dp" finished-at="2019-11-27T10:50:54 MSK">
          <params>
            <param index="0">
              <value>
                <![CDATA[1.0]]>
              </value>
            </param>
          </params>
          <exception class="org.testng.TestException">
            <message>
              <![CDATA[
Method QuadratTest.checkSquare(java.lang.Double)[pri:0, instance:Tests.QuadratTest@5383967b] should have thrown an exception of type class java.lang.RuntimeException]]>
            </message>
            <full-stacktrace>
              <![CDATA[org.testng.TestException: 
Method QuadratTest.checkSquare(java.lang.Double)[pri:0, instance:Tests.QuadratTest@5383967b] should have thrown an exception of type class java.lang.RuntimeException
at org.testng.internal.ExpectedExceptionsHolder.noException(ExpectedExceptionsHolder.java:82)
at org.testng.internal.TestInvoker.considerExceptions(TestInvoker.java:729)
at org.testng.internal.TestInvoker.invokeMethod(TestInvoker.java:616)
at org.testng.internal.TestInvoker.invokeTestMethod(TestInvoker.java:172)
at org.testng.internal.MethodRunner.runInSequence(MethodRunner.java:46)
at org.testng.internal.TestInvoker$MethodInvocationAgent.invoke(TestInvoker.java:804)
at org.testng.internal.TestInvoker.invokeTestMethods(TestInvoker.java:145)
at org.testng.internal.TestMethodWorker.invokeTestMethods(TestMethodWorker.java:146)
at org.testng.internal.TestMethodWorker.run(TestMethodWorker.java:128)
at java.util.ArrayList.forEach(Unknown Source)
at org.testng.TestRunner.privateRun(TestRunner.java:770)
at org.testng.TestRunner.run(TestRunner.java:591)
at org.testng.SuiteRunner.runTest(SuiteRunner.java:402)
at org.testng.SuiteRunner.runSequentially(SuiteRunner.java:396)
at org.testng.SuiteRunner.privateRun(SuiteRunner.java:355)
at org.testng.SuiteRunner.run(SuiteRunner.java:304)
at org.testng.SuiteRunnerWorker.runSuite(SuiteRunnerWorker.java:53)
at org.testng.SuiteRunnerWorker.run(SuiteRunnerWorker.java:96)
at org.testng.TestNG.runSuitesSequentially(TestNG.java:1180)
at org.testng.TestNG.runSuitesLocally(TestNG.java:1102)
at org.testng.TestNG.runSuites(TestNG.java:1032)
at org.testng.TestNG.run(TestNG.java:1000)
at org.testng.remote.AbstractRemoteTestNG.run(AbstractRemoteTestNG.java:115)
at org.testng.remote.RemoteTestNG.initAndRun(RemoteTestNG.java:251)
at org.testng.remote.RemoteTestNG.main(RemoteTestNG.java:77)
]]>
            </full-stacktrace>
          </exception> <!-- org.testng.TestException -->
          <reporter-output>
          </reporter-output>
        </test-method> <!-- checkSquare -->
        <test-method status="FAIL" signature="checkSquare(java.lang.Double)[pri:0, instance:Tests.QuadratTest@5383967b]" name="checkSquare" duration-ms="0" started-at="2019-11-27T10:50:54 MSK" data-provider="dp" finished-at="2019-11-27T10:50:54 MSK">
          <params>
            <param index="0">
              <value>
                <![CDATA[10000.0]]>
              </value>
            </param>
          </params>
          <exception class="org.testng.TestException">
            <message>
              <![CDATA[
Method QuadratTest.checkSquare(java.lang.Double)[pri:0, instance:Tests.QuadratTest@5383967b] should have thrown an exception of type class java.lang.RuntimeException]]>
            </message>
            <full-stacktrace>
              <![CDATA[org.testng.TestException: 
Method QuadratTest.checkSquare(java.lang.Double)[pri:0, instance:Tests.QuadratTest@5383967b] should have thrown an exception of type class java.lang.RuntimeException
at org.testng.internal.ExpectedExceptionsHolder.noException(ExpectedExceptionsHolder.java:82)
at org.testng.internal.TestInvoker.considerExceptions(TestInvoker.java:729)
at org.testng.internal.TestInvoker.invokeMethod(TestInvoker.java:616)
at org.testng.internal.TestInvoker.invokeTestMethod(TestInvoker.java:172)
at org.testng.internal.MethodRunner.runInSequence(MethodRunner.java:46)
at org.testng.internal.TestInvoker$MethodInvocationAgent.invoke(TestInvoker.java:804)
at org.testng.internal.TestInvoker.invokeTestMethods(TestInvoker.java:145)
at org.testng.internal.TestMethodWorker.invokeTestMethods(TestMethodWorker.java:146)
at org.testng.internal.TestMethodWorker.run(TestMethodWorker.java:128)
at java.util.ArrayList.forEach(Unknown Source)
at org.testng.TestRunner.privateRun(TestRunner.java:770)
at org.testng.TestRunner.run(TestRunner.java:591)
at org.testng.SuiteRunner.runTest(SuiteRunner.java:402)
at org.testng.SuiteRunner.runSequentially(SuiteRunner.java:396)
at org.testng.SuiteRunner.privateRun(SuiteRunner.java:355)
at org.testng.SuiteRunner.run(SuiteRunner.java:304)
at org.testng.SuiteRunnerWorker.runSuite(SuiteRunnerWorker.java:53)
at org.testng.SuiteRunnerWorker.run(SuiteRunnerWorker.java:96)
at org.testng.TestNG.runSuitesSequentially(TestNG.java:1180)
at org.testng.TestNG.runSuitesLocally(TestNG.java:1102)
at org.testng.TestNG.runSuites(TestNG.java:1032)
at org.testng.TestNG.run(TestNG.java:1000)
at org.testng.remote.AbstractRemoteTestNG.run(AbstractRemoteTestNG.java:115)
at org.testng.remote.RemoteTestNG.initAndRun(RemoteTestNG.java:251)
at org.testng.remote.RemoteTestNG.main(RemoteTestNG.java:77)
]]>
            </full-stacktrace>
          </exception> <!-- org.testng.TestException -->
          <reporter-output>
          </reporter-output>
        </test-method> <!-- checkSquare -->
        <test-method status="FAIL" signature="checkSquare(java.lang.Double)[pri:0, instance:Tests.QuadratTest@5383967b]" name="checkSquare" duration-ms="0" started-at="2019-11-27T10:50:54 MSK" data-provider="dp" finished-at="2019-11-27T10:50:54 MSK">
          <params>
            <param index="0">
              <value>
                <![CDATA[2.5]]>
              </value>
            </param>
          </params>
          <exception class="org.testng.TestException">
            <message>
              <![CDATA[
Method QuadratTest.checkSquare(java.lang.Double)[pri:0, instance:Tests.QuadratTest@5383967b] should have thrown an exception of type class java.lang.RuntimeException]]>
            </message>
            <full-stacktrace>
              <![CDATA[org.testng.TestException: 
Method QuadratTest.checkSquare(java.lang.Double)[pri:0, instance:Tests.QuadratTest@5383967b] should have thrown an exception of type class java.lang.RuntimeException
at org.testng.internal.ExpectedExceptionsHolder.noException(ExpectedExceptionsHolder.java:82)
at org.testng.internal.TestInvoker.considerExceptions(TestInvoker.java:729)
at org.testng.internal.TestInvoker.invokeMethod(TestInvoker.java:616)
at org.testng.internal.TestInvoker.invokeTestMethod(TestInvoker.java:172)
at org.testng.internal.MethodRunner.runInSequence(MethodRunner.java:46)
at org.testng.internal.TestInvoker$MethodInvocationAgent.invoke(TestInvoker.java:804)
at org.testng.internal.TestInvoker.invokeTestMethods(TestInvoker.java:145)
at org.testng.internal.TestMethodWorker.invokeTestMethods(TestMethodWorker.java:146)
at org.testng.internal.TestMethodWorker.run(TestMethodWorker.java:128)
at java.util.ArrayList.forEach(Unknown Source)
at org.testng.TestRunner.privateRun(TestRunner.java:770)
at org.testng.TestRunner.run(TestRunner.java:591)
at org.testng.SuiteRunner.runTest(SuiteRunner.java:402)
at org.testng.SuiteRunner.runSequentially(SuiteRunner.java:396)
at org.testng.SuiteRunner.privateRun(SuiteRunner.java:355)
at org.testng.SuiteRunner.run(SuiteRunner.java:304)
at org.testng.SuiteRunnerWorker.runSuite(SuiteRunnerWorker.java:53)
at org.testng.SuiteRunnerWorker.run(SuiteRunnerWorker.java:96)
at org.testng.TestNG.runSuitesSequentially(TestNG.java:1180)
at org.testng.TestNG.runSuitesLocally(TestNG.java:1102)
at org.testng.TestNG.runSuites(TestNG.java:1032)
at org.testng.TestNG.run(TestNG.java:1000)
at org.testng.remote.AbstractRemoteTestNG.run(AbstractRemoteTestNG.java:115)
at org.testng.remote.RemoteTestNG.initAndRun(RemoteTestNG.java:251)
at org.testng.remote.RemoteTestNG.main(RemoteTestNG.java:77)
]]>
            </full-stacktrace>
          </exception> <!-- org.testng.TestException -->
          <reporter-output>
          </reporter-output>
        </test-method> <!-- checkSquare -->
        <test-method status="FAIL" signature="checkPerimetr(java.lang.Double)[pri:1, instance:Tests.QuadratTest@5383967b]" name="checkPerimetr" duration-ms="1" started-at="2019-11-27T10:50:54 MSK" data-provider="dp" finished-at="2019-11-27T10:50:54 MSK">
          <params>
            <param index="0">
              <value>
                <![CDATA[1.0]]>
              </value>
            </param>
          </params>
          <exception class="org.testng.TestException">
            <message>
              <![CDATA[
Method QuadratTest.checkPerimetr(java.lang.Double)[pri:1, instance:Tests.QuadratTest@5383967b] should have thrown an exception of type class java.lang.RuntimeException]]>
            </message>
            <full-stacktrace>
              <![CDATA[org.testng.TestException: 
Method QuadratTest.checkPerimetr(java.lang.Double)[pri:1, instance:Tests.QuadratTest@5383967b] should have thrown an exception of type class java.lang.RuntimeException
at org.testng.internal.ExpectedExceptionsHolder.noException(ExpectedExceptionsHolder.java:82)
at org.testng.internal.TestInvoker.considerExceptions(TestInvoker.java:729)
at org.testng.internal.TestInvoker.invokeMethod(TestInvoker.java:616)
at org.testng.internal.TestInvoker.invokeTestMethod(TestInvoker.java:172)
at org.testng.internal.MethodRunner.runInSequence(MethodRunner.java:46)
at org.testng.internal.TestInvoker$MethodInvocationAgent.invoke(TestInvoker.java:804)
at org.testng.internal.TestInvoker.invokeTestMethods(TestInvoker.java:145)
at org.testng.internal.TestMethodWorker.invokeTestMethods(TestMethodWorker.java:146)
at org.testng.internal.TestMethodWorker.run(TestMethodWorker.java:128)
at java.util.ArrayList.forEach(Unknown Source)
at org.testng.TestRunner.privateRun(TestRunner.java:770)
at org.testng.TestRunner.run(TestRunner.java:591)
at org.testng.SuiteRunner.runTest(SuiteRunner.java:402)
at org.testng.SuiteRunner.runSequentially(SuiteRunner.java:396)
at org.testng.SuiteRunner.privateRun(SuiteRunner.java:355)
at org.testng.SuiteRunner.run(SuiteRunner.java:304)
at org.testng.SuiteRunnerWorker.runSuite(SuiteRunnerWorker.java:53)
at org.testng.SuiteRunnerWorker.run(SuiteRunnerWorker.java:96)
at org.testng.TestNG.runSuitesSequentially(TestNG.java:1180)
at org.testng.TestNG.runSuitesLocally(TestNG.java:1102)
at org.testng.TestNG.runSuites(TestNG.java:1032)
at org.testng.TestNG.run(TestNG.java:1000)
at org.testng.remote.AbstractRemoteTestNG.run(AbstractRemoteTestNG.java:115)
at org.testng.remote.RemoteTestNG.initAndRun(RemoteTestNG.java:251)
at org.testng.remote.RemoteTestNG.main(RemoteTestNG.java:77)
]]>
            </full-stacktrace>
          </exception> <!-- org.testng.TestException -->
          <reporter-output>
          </reporter-output>
        </test-method> <!-- checkPerimetr -->
        <test-method status="FAIL" signature="checkPerimetr(java.lang.Double)[pri:1, instance:Tests.QuadratTest@5383967b]" name="checkPerimetr" duration-ms="0" started-at="2019-11-27T10:50:54 MSK" data-provider="dp" finished-at="2019-11-27T10:50:54 MSK">
          <params>
            <param index="0">
              <value>
                <![CDATA[10000.0]]>
              </value>
            </param>
          </params>
          <exception class="org.testng.TestException">
            <message>
              <![CDATA[
Method QuadratTest.checkPerimetr(java.lang.Double)[pri:1, instance:Tests.QuadratTest@5383967b] should have thrown an exception of type class java.lang.RuntimeException]]>
            </message>
            <full-stacktrace>
              <![CDATA[org.testng.TestException: 
Method QuadratTest.checkPerimetr(java.lang.Double)[pri:1, instance:Tests.QuadratTest@5383967b] should have thrown an exception of type class java.lang.RuntimeException
at org.testng.internal.ExpectedExceptionsHolder.noException(ExpectedExceptionsHolder.java:82)
at org.testng.internal.TestInvoker.considerExceptions(TestInvoker.java:729)
at org.testng.internal.TestInvoker.invokeMethod(TestInvoker.java:616)
at org.testng.internal.TestInvoker.invokeTestMethod(TestInvoker.java:172)
at org.testng.internal.MethodRunner.runInSequence(MethodRunner.java:46)
at org.testng.internal.TestInvoker$MethodInvocationAgent.invoke(TestInvoker.java:804)
at org.testng.internal.TestInvoker.invokeTestMethods(TestInvoker.java:145)
at org.testng.internal.TestMethodWorker.invokeTestMethods(TestMethodWorker.java:146)
at org.testng.internal.TestMethodWorker.run(TestMethodWorker.java:128)
at java.util.ArrayList.forEach(Unknown Source)
at org.testng.TestRunner.privateRun(TestRunner.java:770)
at org.testng.TestRunner.run(TestRunner.java:591)
at org.testng.SuiteRunner.runTest(SuiteRunner.java:402)
at org.testng.SuiteRunner.runSequentially(SuiteRunner.java:396)
at org.testng.SuiteRunner.privateRun(SuiteRunner.java:355)
at org.testng.SuiteRunner.run(SuiteRunner.java:304)
at org.testng.SuiteRunnerWorker.runSuite(SuiteRunnerWorker.java:53)
at org.testng.SuiteRunnerWorker.run(SuiteRunnerWorker.java:96)
at org.testng.TestNG.runSuitesSequentially(TestNG.java:1180)
at org.testng.TestNG.runSuitesLocally(TestNG.java:1102)
at org.testng.TestNG.runSuites(TestNG.java:1032)
at org.testng.TestNG.run(TestNG.java:1000)
at org.testng.remote.AbstractRemoteTestNG.run(AbstractRemoteTestNG.java:115)
at org.testng.remote.RemoteTestNG.initAndRun(RemoteTestNG.java:251)
at org.testng.remote.RemoteTestNG.main(RemoteTestNG.java:77)
]]>
            </full-stacktrace>
          </exception> <!-- org.testng.TestException -->
          <reporter-output>
          </reporter-output>
        </test-method> <!-- checkPerimetr -->
        <test-method status="FAIL" signature="checkPerimetr(java.lang.Double)[pri:1, instance:Tests.QuadratTest@5383967b]" name="checkPerimetr" duration-ms="0" started-at="2019-11-27T10:50:54 MSK" data-provider="dp" finished-at="2019-11-27T10:50:54 MSK">
          <params>
            <param index="0">
              <value>
                <![CDATA[2.5]]>
              </value>
            </param>
          </params>
          <exception class="org.testng.TestException">
            <message>
              <![CDATA[
Method QuadratTest.checkPerimetr(java.lang.Double)[pri:1, instance:Tests.QuadratTest@5383967b] should have thrown an exception of type class java.lang.RuntimeException]]>
            </message>
            <full-stacktrace>
              <![CDATA[org.testng.TestException: 
Method QuadratTest.checkPerimetr(java.lang.Double)[pri:1, instance:Tests.QuadratTest@5383967b] should have thrown an exception of type class java.lang.RuntimeException
at org.testng.internal.ExpectedExceptionsHolder.noException(ExpectedExceptionsHolder.java:82)
at org.testng.internal.TestInvoker.considerExceptions(TestInvoker.java:729)
at org.testng.internal.TestInvoker.invokeMethod(TestInvoker.java:616)
at org.testng.internal.TestInvoker.invokeTestMethod(TestInvoker.java:172)
at org.testng.internal.MethodRunner.runInSequence(MethodRunner.java:46)
at org.testng.internal.TestInvoker$MethodInvocationAgent.invoke(TestInvoker.java:804)
at org.testng.internal.TestInvoker.invokeTestMethods(TestInvoker.java:145)
at org.testng.internal.TestMethodWorker.invokeTestMethods(TestMethodWorker.java:146)
at org.testng.internal.TestMethodWorker.run(TestMethodWorker.java:128)
at java.util.ArrayList.forEach(Unknown Source)
at org.testng.TestRunner.privateRun(TestRunner.java:770)
at org.testng.TestRunner.run(TestRunner.java:591)
at org.testng.SuiteRunner.runTest(SuiteRunner.java:402)
at org.testng.SuiteRunner.runSequentially(SuiteRunner.java:396)
at org.testng.SuiteRunner.privateRun(SuiteRunner.java:355)
at org.testng.SuiteRunner.run(SuiteRunner.java:304)
at org.testng.SuiteRunnerWorker.runSuite(SuiteRunnerWorker.java:53)
at org.testng.SuiteRunnerWorker.run(SuiteRunnerWorker.java:96)
at org.testng.TestNG.runSuitesSequentially(TestNG.java:1180)
at org.testng.TestNG.runSuitesLocally(TestNG.java:1102)
at org.testng.TestNG.runSuites(TestNG.java:1032)
at org.testng.TestNG.run(TestNG.java:1000)
at org.testng.remote.AbstractRemoteTestNG.run(AbstractRemoteTestNG.java:115)
at org.testng.remote.RemoteTestNG.initAndRun(RemoteTestNG.java:251)
at org.testng.remote.RemoteTestNG.main(RemoteTestNG.java:77)
]]>
            </full-stacktrace>
          </exception> <!-- org.testng.TestException -->
          <reporter-output>
          </reporter-output>
        </test-method> <!-- checkPerimetr -->
      </class> <!-- Tests.QuadratTest -->
    </test> <!-- Default test -->
  </suite> <!-- Default suite -->
</testng-results>
